{"message": "Started server process [43012]", "color_message": "Started server process [\u001b[36m%d\u001b[0m]"}
{"message": "Waiting for application startup."}
{"message": "Application startup complete."}
{"message": "Process time: 228.06ms"}
{"message": "Exception in ASGI application\n", "exc_info": "Traceback (most recent call last):\n  File \"/usr/local/lib/python3.9/site-packages/sqlalchemy/engine/base.py\", line 3280, in _wrap_pool_connect\n    return fn()\n  File \"/usr/local/lib/python3.9/site-packages/sqlalchemy/pool/base.py\", line 310, in connect\n    return _ConnectionFairy._checkout(self)\n  File \"/usr/local/lib/python3.9/site-packages/sqlalchemy/pool/base.py\", line 868, in _checkout\n    fairy = _ConnectionRecord.checkout(pool)\n  File \"/usr/local/lib/python3.9/site-packages/sqlalchemy/pool/base.py\", line 476, in checkout\n    rec = pool._do_get()\n  File \"/usr/local/lib/python3.9/site-packages/sqlalchemy/pool/impl.py\", line 146, in _do_get\n    self._dec_overflow()\n  File \"/usr/local/lib/python3.9/site-packages/sqlalchemy/util/langhelpers.py\", line 70, in __exit__\n    compat.raise_(\n  File \"/usr/local/lib/python3.9/site-packages/sqlalchemy/util/compat.py\", line 207, in raise_\n    raise exception\n  File \"/usr/local/lib/python3.9/site-packages/sqlalchemy/pool/impl.py\", line 143, in _do_get\n    return self._create_connection()\n  File \"/usr/local/lib/python3.9/site-packages/sqlalchemy/pool/base.py\", line 256, in _create_connection\n    return _ConnectionRecord(self)\n  File \"/usr/local/lib/python3.9/site-packages/sqlalchemy/pool/base.py\", line 371, in __init__\n    self.__connect()\n  File \"/usr/local/lib/python3.9/site-packages/sqlalchemy/pool/base.py\", line 666, in __connect\n    pool.logger.debug(\"Error on connect(): %s\", e)\n  File \"/usr/local/lib/python3.9/site-packages/sqlalchemy/util/langhelpers.py\", line 70, in __exit__\n    compat.raise_(\n  File \"/usr/local/lib/python3.9/site-packages/sqlalchemy/util/compat.py\", line 207, in raise_\n    raise exception\n  File \"/usr/local/lib/python3.9/site-packages/sqlalchemy/pool/base.py\", line 661, in __connect\n    self.dbapi_connection = connection = pool._invoke_creator(self)\n  File \"/usr/local/lib/python3.9/site-packages/sqlalchemy/engine/create.py\", line 590, in connect\n    return dialect.connect(*cargs, **cparams)\n  File \"/usr/local/lib/python3.9/site-packages/sqlalchemy/engine/default.py\", line 597, in connect\n    return self.dbapi.connect(*cargs, **cparams)\n  File \"/usr/local/lib/python3.9/site-packages/psycopg2/__init__.py\", line 122, in connect\n    conn = _connect(dsn, connection_factory=connection_factory, **kwasync)\npsycopg2.OperationalError: connection to server at \"localhost\" (::1), port 5432 failed: Connection refused\n\tIs the server running on that host and accepting TCP/IP connections?\nconnection to server at \"localhost\" (127.0.0.1), port 5432 failed: Connection refused\n\tIs the server running on that host and accepting TCP/IP connections?\n\n\nThe above exception was the direct cause of the following exception:\n\nTraceback (most recent call last):\n  File \"/usr/local/lib/python3.9/site-packages/uvicorn/protocols/http/h11_impl.py\", line 403, in run_asgi\n    result = await app(self.scope, self.receive, self.send)\n  File \"/usr/local/lib/python3.9/site-packages/uvicorn/middleware/proxy_headers.py\", line 78, in __call__\n    return await self.app(scope, receive, send)\n  File \"/usr/local/lib/python3.9/site-packages/fastapi/applications.py\", line 269, in __call__\n    await super().__call__(scope, receive, send)\n  File \"/usr/local/lib/python3.9/site-packages/starlette/applications.py\", line 124, in __call__\n    await self.middleware_stack(scope, receive, send)\n  File \"/usr/local/lib/python3.9/site-packages/starlette/middleware/errors.py\", line 184, in __call__\n    raise exc\n  File \"/usr/local/lib/python3.9/site-packages/starlette/middleware/errors.py\", line 162, in __call__\n    await self.app(scope, receive, _send)\n  File \"/usr/local/lib/python3.9/site-packages/starlette/exceptions.py\", line 93, in __call__\n    raise exc\n  File \"/usr/local/lib/python3.9/site-packages/starlette/exceptions.py\", line 82, in __call__\n    await self.app(scope, receive, sender)\n  File \"/usr/local/lib/python3.9/site-packages/fastapi/middleware/asyncexitstack.py\", line 21, in __call__\n    raise e\n  File \"/usr/local/lib/python3.9/site-packages/fastapi/middleware/asyncexitstack.py\", line 18, in __call__\n    await self.app(scope, receive, send)\n  File \"/usr/local/lib/python3.9/site-packages/starlette/routing.py\", line 670, in __call__\n    await route.handle(scope, receive, send)\n  File \"/usr/local/lib/python3.9/site-packages/starlette/routing.py\", line 266, in handle\n    await self.app(scope, receive, send)\n  File \"/usr/local/lib/python3.9/site-packages/starlette/routing.py\", line 65, in app\n    response = await func(request)\n  File \"/usr/local/lib/python3.9/site-packages/fastapi/routing.py\", line 227, in app\n    raw_response = await run_endpoint_function(\n  File \"/usr/local/lib/python3.9/site-packages/fastapi/routing.py\", line 162, in run_endpoint_function\n    return await run_in_threadpool(dependant.call, **values)\n  File \"/usr/local/lib/python3.9/site-packages/starlette/concurrency.py\", line 41, in run_in_threadpool\n    return await anyio.to_thread.run_sync(func, *args)\n  File \"/usr/local/lib/python3.9/site-packages/anyio/to_thread.py\", line 31, in run_sync\n    return await get_asynclib().run_sync_in_worker_thread(\n  File \"/usr/local/lib/python3.9/site-packages/anyio/_backends/_asyncio.py\", line 937, in run_sync_in_worker_thread\n    return await future\n  File \"/usr/local/lib/python3.9/site-packages/anyio/_backends/_asyncio.py\", line 867, in run\n    result = context.run(func, *args)\n  File \"/Users/bernattorres/me/stylizer/app/./routes/api/styles.py\", line 32, in stylize_image\n    return transfer_style_handler.handle(file, style, background_tasks, db)\n  File \"/Users/bernattorres/me/stylizer/app/./handlers/transfer_style.py\", line 34, in handle\n    transformation.create(db=db, obj_in=TransformationCreate(style=style))\n  File \"/Users/bernattorres/me/stylizer/app/./repositories/base.py\", line 38, in create\n    db.commit()\n  File \"/usr/local/lib/python3.9/site-packages/sqlalchemy/orm/session.py\", line 1435, in commit\n    self._transaction.commit(_to_root=self.future)\n  File \"/usr/local/lib/python3.9/site-packages/sqlalchemy/orm/session.py\", line 829, in commit\n    self._prepare_impl()\n  File \"/usr/local/lib/python3.9/site-packages/sqlalchemy/orm/session.py\", line 808, in _prepare_impl\n    self.session.flush()\n  File \"/usr/local/lib/python3.9/site-packages/sqlalchemy/orm/session.py\", line 3367, in flush\n    self._flush(objects)\n  File \"/usr/local/lib/python3.9/site-packages/sqlalchemy/orm/session.py\", line 3507, in _flush\n    transaction.rollback(_capture_exception=True)\n  File \"/usr/local/lib/python3.9/site-packages/sqlalchemy/util/langhelpers.py\", line 70, in __exit__\n    compat.raise_(\n  File \"/usr/local/lib/python3.9/site-packages/sqlalchemy/util/compat.py\", line 207, in raise_\n    raise exception\n  File \"/usr/local/lib/python3.9/site-packages/sqlalchemy/orm/session.py\", line 3467, in _flush\n    flush_context.execute()\n  File \"/usr/local/lib/python3.9/site-packages/sqlalchemy/orm/unitofwork.py\", line 456, in execute\n    rec.execute(self)\n  File \"/usr/local/lib/python3.9/site-packages/sqlalchemy/orm/unitofwork.py\", line 630, in execute\n    util.preloaded.orm_persistence.save_obj(\n  File \"/usr/local/lib/python3.9/site-packages/sqlalchemy/orm/persistence.py\", line 212, in save_obj\n    for (\n  File \"/usr/local/lib/python3.9/site-packages/sqlalchemy/orm/persistence.py\", line 373, in _organize_states_for_save\n    for state, dict_, mapper, connection in _connections_for_states(\n  File \"/usr/local/lib/python3.9/site-packages/sqlalchemy/orm/persistence.py\", line 1737, in _connections_for_states\n    connection = uowtransaction.transaction.connection(base_mapper)\n  File \"/usr/local/lib/python3.9/site-packages/sqlalchemy/orm/session.py\", line 626, in connection\n    return self._connection_for_bind(bind, execution_options)\n  File \"/usr/local/lib/python3.9/site-packages/sqlalchemy/orm/session.py\", line 735, in _connection_for_bind\n    conn = self._parent._connection_for_bind(bind, execution_options)\n  File \"/usr/local/lib/python3.9/site-packages/sqlalchemy/orm/session.py\", line 747, in _connection_for_bind\n    conn = bind.connect()\n  File \"/usr/local/lib/python3.9/site-packages/sqlalchemy/engine/base.py\", line 3234, in connect\n    return self._connection_cls(self, close_with_result=close_with_result)\n  File \"/usr/local/lib/python3.9/site-packages/sqlalchemy/engine/base.py\", line 96, in __init__\n    else engine.raw_connection()\n  File \"/usr/local/lib/python3.9/site-packages/sqlalchemy/engine/base.py\", line 3313, in raw_connection\n    return self._wrap_pool_connect(self.pool.connect, _connection)\n  File \"/usr/local/lib/python3.9/site-packages/sqlalchemy/engine/base.py\", line 3283, in _wrap_pool_connect\n    Connection._handle_dbapi_exception_noconnection(\n  File \"/usr/local/lib/python3.9/site-packages/sqlalchemy/engine/base.py\", line 2117, in _handle_dbapi_exception_noconnection\n    util.raise_(\n  File \"/usr/local/lib/python3.9/site-packages/sqlalchemy/util/compat.py\", line 207, in raise_\n    raise exception\n  File \"/usr/local/lib/python3.9/site-packages/sqlalchemy/engine/base.py\", line 3280, in _wrap_pool_connect\n    return fn()\n  File \"/usr/local/lib/python3.9/site-packages/sqlalchemy/pool/base.py\", line 310, in connect\n    return _ConnectionFairy._checkout(self)\n  File \"/usr/local/lib/python3.9/site-packages/sqlalchemy/pool/base.py\", line 868, in _checkout\n    fairy = _ConnectionRecord.checkout(pool)\n  File \"/usr/local/lib/python3.9/site-packages/sqlalchemy/pool/base.py\", line 476, in checkout\n    rec = pool._do_get()\n  File \"/usr/local/lib/python3.9/site-packages/sqlalchemy/pool/impl.py\", line 146, in _do_get\n    self._dec_overflow()\n  File \"/usr/local/lib/python3.9/site-packages/sqlalchemy/util/langhelpers.py\", line 70, in __exit__\n    compat.raise_(\n  File \"/usr/local/lib/python3.9/site-packages/sqlalchemy/util/compat.py\", line 207, in raise_\n    raise exception\n  File \"/usr/local/lib/python3.9/site-packages/sqlalchemy/pool/impl.py\", line 143, in _do_get\n    return self._create_connection()\n  File \"/usr/local/lib/python3.9/site-packages/sqlalchemy/pool/base.py\", line 256, in _create_connection\n    return _ConnectionRecord(self)\n  File \"/usr/local/lib/python3.9/site-packages/sqlalchemy/pool/base.py\", line 371, in __init__\n    self.__connect()\n  File \"/usr/local/lib/python3.9/site-packages/sqlalchemy/pool/base.py\", line 666, in __connect\n    pool.logger.debug(\"Error on connect(): %s\", e)\n  File \"/usr/local/lib/python3.9/site-packages/sqlalchemy/util/langhelpers.py\", line 70, in __exit__\n    compat.raise_(\n  File \"/usr/local/lib/python3.9/site-packages/sqlalchemy/util/compat.py\", line 207, in raise_\n    raise exception\n  File \"/usr/local/lib/python3.9/site-packages/sqlalchemy/pool/base.py\", line 661, in __connect\n    self.dbapi_connection = connection = pool._invoke_creator(self)\n  File \"/usr/local/lib/python3.9/site-packages/sqlalchemy/engine/create.py\", line 590, in connect\n    return dialect.connect(*cargs, **cparams)\n  File \"/usr/local/lib/python3.9/site-packages/sqlalchemy/engine/default.py\", line 597, in connect\n    return self.dbapi.connect(*cargs, **cparams)\n  File \"/usr/local/lib/python3.9/site-packages/psycopg2/__init__.py\", line 122, in connect\n    conn = _connect(dsn, connection_factory=connection_factory, **kwasync)\nsqlalchemy.exc.OperationalError: (psycopg2.OperationalError) connection to server at \"localhost\" (::1), port 5432 failed: Connection refused\n\tIs the server running on that host and accepting TCP/IP connections?\nconnection to server at \"localhost\" (127.0.0.1), port 5432 failed: Connection refused\n\tIs the server running on that host and accepting TCP/IP connections?\n\n(Background on this error at: https://sqlalche.me/e/14/e3q8)"}
{"message": "Shutting down"}
{"message": "Waiting for application shutdown."}
{"message": "Application shutdown complete."}
{"message": "Finished server process [43012]", "color_message": "Finished server process [\u001b[36m%d\u001b[0m]"}
{"message": "Started server process [43207]", "color_message": "Started server process [\u001b[36m%d\u001b[0m]"}
{"message": "Started server process [43207]", "color_message": "Started server process [\u001b[36m%d\u001b[0m]"}
{"message": "Waiting for application startup."}
{"message": "Waiting for application startup."}
{"message": "Application startup complete."}
{"message": "Application startup complete."}
{"message": "Exception in ASGI application\n", "exc_info": "Traceback (most recent call last):\n  File \"/usr/local/lib/python3.9/site-packages/uvicorn/protocols/http/h11_impl.py\", line 403, in run_asgi\n    result = await app(self.scope, self.receive, self.send)\n  File \"/usr/local/lib/python3.9/site-packages/uvicorn/middleware/proxy_headers.py\", line 78, in __call__\n    return await self.app(scope, receive, send)\n  File \"/usr/local/lib/python3.9/site-packages/fastapi/applications.py\", line 269, in __call__\n    await super().__call__(scope, receive, send)\n  File \"/usr/local/lib/python3.9/site-packages/starlette/applications.py\", line 124, in __call__\n    await self.middleware_stack(scope, receive, send)\n  File \"/usr/local/lib/python3.9/site-packages/starlette/middleware/errors.py\", line 184, in __call__\n    raise exc\n  File \"/usr/local/lib/python3.9/site-packages/starlette/middleware/errors.py\", line 162, in __call__\n    await self.app(scope, receive, _send)\n  File \"/usr/local/lib/python3.9/site-packages/starlette/exceptions.py\", line 93, in __call__\n    raise exc\n  File \"/usr/local/lib/python3.9/site-packages/starlette/exceptions.py\", line 82, in __call__\n    await self.app(scope, receive, sender)\n  File \"/usr/local/lib/python3.9/site-packages/fastapi/middleware/asyncexitstack.py\", line 21, in __call__\n    raise e\n  File \"/usr/local/lib/python3.9/site-packages/fastapi/middleware/asyncexitstack.py\", line 18, in __call__\n    await self.app(scope, receive, send)\n  File \"/usr/local/lib/python3.9/site-packages/starlette/routing.py\", line 670, in __call__\n    await route.handle(scope, receive, send)\n  File \"/usr/local/lib/python3.9/site-packages/starlette/routing.py\", line 266, in handle\n    await self.app(scope, receive, send)\n  File \"/usr/local/lib/python3.9/site-packages/starlette/routing.py\", line 65, in app\n    response = await func(request)\n  File \"/usr/local/lib/python3.9/site-packages/fastapi/routing.py\", line 227, in app\n    raw_response = await run_endpoint_function(\n  File \"/usr/local/lib/python3.9/site-packages/fastapi/routing.py\", line 162, in run_endpoint_function\n    return await run_in_threadpool(dependant.call, **values)\n  File \"/usr/local/lib/python3.9/site-packages/starlette/concurrency.py\", line 41, in run_in_threadpool\n    return await anyio.to_thread.run_sync(func, *args)\n  File \"/usr/local/lib/python3.9/site-packages/anyio/to_thread.py\", line 31, in run_sync\n    return await get_asynclib().run_sync_in_worker_thread(\n  File \"/usr/local/lib/python3.9/site-packages/anyio/_backends/_asyncio.py\", line 937, in run_sync_in_worker_thread\n    return await future\n  File \"/usr/local/lib/python3.9/site-packages/anyio/_backends/_asyncio.py\", line 867, in run\n    result = context.run(func, *args)\n  File \"/Users/bernattorres/me/stylizer/app/./routes/index/base.py\", line 19, in index\n    ogger.info(\"Process times\")\nNameError: name 'ogger' is not defined"}
{"message": "Exception in ASGI application\n", "exc_info": "Traceback (most recent call last):\n  File \"/usr/local/lib/python3.9/site-packages/uvicorn/protocols/http/h11_impl.py\", line 403, in run_asgi\n    result = await app(self.scope, self.receive, self.send)\n  File \"/usr/local/lib/python3.9/site-packages/uvicorn/middleware/proxy_headers.py\", line 78, in __call__\n    return await self.app(scope, receive, send)\n  File \"/usr/local/lib/python3.9/site-packages/fastapi/applications.py\", line 269, in __call__\n    await super().__call__(scope, receive, send)\n  File \"/usr/local/lib/python3.9/site-packages/starlette/applications.py\", line 124, in __call__\n    await self.middleware_stack(scope, receive, send)\n  File \"/usr/local/lib/python3.9/site-packages/starlette/middleware/errors.py\", line 184, in __call__\n    raise exc\n  File \"/usr/local/lib/python3.9/site-packages/starlette/middleware/errors.py\", line 162, in __call__\n    await self.app(scope, receive, _send)\n  File \"/usr/local/lib/python3.9/site-packages/starlette/exceptions.py\", line 93, in __call__\n    raise exc\n  File \"/usr/local/lib/python3.9/site-packages/starlette/exceptions.py\", line 82, in __call__\n    await self.app(scope, receive, sender)\n  File \"/usr/local/lib/python3.9/site-packages/fastapi/middleware/asyncexitstack.py\", line 21, in __call__\n    raise e\n  File \"/usr/local/lib/python3.9/site-packages/fastapi/middleware/asyncexitstack.py\", line 18, in __call__\n    await self.app(scope, receive, send)\n  File \"/usr/local/lib/python3.9/site-packages/starlette/routing.py\", line 670, in __call__\n    await route.handle(scope, receive, send)\n  File \"/usr/local/lib/python3.9/site-packages/starlette/routing.py\", line 266, in handle\n    await self.app(scope, receive, send)\n  File \"/usr/local/lib/python3.9/site-packages/starlette/routing.py\", line 65, in app\n    response = await func(request)\n  File \"/usr/local/lib/python3.9/site-packages/fastapi/routing.py\", line 227, in app\n    raw_response = await run_endpoint_function(\n  File \"/usr/local/lib/python3.9/site-packages/fastapi/routing.py\", line 162, in run_endpoint_function\n    return await run_in_threadpool(dependant.call, **values)\n  File \"/usr/local/lib/python3.9/site-packages/starlette/concurrency.py\", line 41, in run_in_threadpool\n    return await anyio.to_thread.run_sync(func, *args)\n  File \"/usr/local/lib/python3.9/site-packages/anyio/to_thread.py\", line 31, in run_sync\n    return await get_asynclib().run_sync_in_worker_thread(\n  File \"/usr/local/lib/python3.9/site-packages/anyio/_backends/_asyncio.py\", line 937, in run_sync_in_worker_thread\n    return await future\n  File \"/usr/local/lib/python3.9/site-packages/anyio/_backends/_asyncio.py\", line 867, in run\n    result = context.run(func, *args)\n  File \"/Users/bernattorres/me/stylizer/app/./routes/index/base.py\", line 19, in index\n    ogger.info(\"Process times\")\nNameError: name 'ogger' is not defined"}
{"message": "Shutting down"}
{"message": "Shutting down"}
{"message": "Waiting for application shutdown."}
{"message": "Waiting for application shutdown."}
{"message": "Application shutdown complete."}
{"message": "Application shutdown complete."}
{"message": "Finished server process [43207]", "color_message": "Finished server process [\u001b[36m%d\u001b[0m]"}
{"message": "Finished server process [43207]", "color_message": "Finished server process [\u001b[36m%d\u001b[0m]"}
{"message": "Started server process [43236]", "color_message": "Started server process [\u001b[36m%d\u001b[0m]"}
{"message": "Started server process [43236]", "color_message": "Started server process [\u001b[36m%d\u001b[0m]"}
{"message": "Waiting for application startup."}
{"message": "Waiting for application startup."}
{"message": "Application startup complete."}
{"message": "Application startup complete."}
{"message": "Process times"}
{"message": "Process times"}
{"message": "Shutting down"}
{"message": "Shutting down"}
{"message": "Waiting for application shutdown."}
{"message": "Waiting for application shutdown."}
{"message": "Application shutdown complete."}
{"message": "Application shutdown complete."}
{"message": "Finished server process [43236]", "color_message": "Finished server process [\u001b[36m%d\u001b[0m]"}
{"message": "Finished server process [43236]", "color_message": "Finished server process [\u001b[36m%d\u001b[0m]"}
